Workbook

Sheet automobile_dataset
A1: Make | B1: Model | C1: Year | D1: Fuel_Type | E1: Transmission | F1: Engine_Size | G1: Mileage | H1: Horsepower | I1: Torque | J1: Owners | K1: Accident_History | L1: Service_History | M1: Color | N1: Body_Type | O1: Drivetrain | P1: Fuel_Efficiency | Q1: Location | R1: Selling_Price
A2: Mercedes-Benz | B2: GLE | C2: 2024 | D2: Petrol | E2: Automatic | F2: 2.3 | G2: 100 | H2: 186 | I2: 196 | J2: 1 | K2: 0 | M2: Silver | N2: SUV | O2: AWD | P2: 30 | Q2: IL | R2: 64140
A3: Hyundai | B3: Tucson | C3: 2008 | D3: Petrol | E3: Automatic | F3: 2.3 | G3: 387035 | H3: 189 | I3: 190 | J3: 4 | K3: 0 | M3: Blue | N3: SUV | O3: FWD | P3: 35 | Q3: FL | R3: 500
A4: Volkswagen | B4: Golf | C4: 2021 | D4: Hybrid | F4: 1.9 | G4: 46054 | H4: 158 | I4: 153 | J4: 1 | K4: 0 | L4: Partial Service | M4: Gray | N4: Hatchback | O4: AWD | P4: 43 | Q4: NY | R4: 16429
A5: Chevrolet | B5: Tahoe | C5: 2005 | D5: Petrol | F5: 2.2 | G5: 141302 | H5: 169 | I5: 165 | J5: 5 | K5: 1 | L5: No Service | M5: Blue | N5: SUV | O5: AWD | Q5: FL | R5: 2199
A6: Toyota | B6: Camry | C6: 2022 | D6: Petrol | E6: Automatic | F6: 1.9 | G6: 32813 | H6: 149 | I6: 141 | J6: 1 | K6: 0 | L6: Full Service | M6: Brown | N6: Sedan | O6: FWD | P6: 38 | Q6: CA | R6: 21792
A7: Chevrolet | B7: Equinox | C7: 2008 | D7: Petrol | F7: 2.7 | G7: 60654 | H7: 212 | I7: 207 | J7: 3 | K7: 0 | M7: Blue | N7: SUV | O7: AWD | P7: 25 | Q7: TX | R7: 3421
A8: Nissan | B8: Sentra | C8: 2022 | D8: Petrol | E8: Automatic | F8: 2.2 | G8: 7444 | I8: 180 | J8: 1 | K8: 0 | L8: Full Service | M8: Gray | N8: Sedan | O8: AWD | P8: 34 | Q8: IL | R8: 17145
A9: Mercedes-Benz | B9: C-Class | C9: 2022 | D9: Petrol | E9: Automatic | F9: 2.3 | G9: 32133 | H9: 180 | I9: 162 | J9: 1 | K9: 0 | L9: Partial Service | M9: Green | N9: Sedan | O9: FWD | P9: 35 | Q9: NY | R9: 31416
A10: BMW | B10: X3 | C10: 2023 | D10: Petrol | E10: Automatic | G10: 1553 | H10: 203 | I10: 179 | J10: 1 | K10: 0 | L10: Full Service | N10: SUV | O10: AWD | P10: 25 | Q10: FL | R10: 43914
A11: Honda | B11: Pilot | C11: 2020 | D11: Hybrid | E11: Automatic | F11: 2.1 | G11: 12494 | H11: 178 | I11: 168 | J11: 1 | L11: No Service | M11: Blue | N11: SUV | O11: FWD | P11: 44 | Q11: NC | R11: 22311
A12: Hyundai | B12: Santa Fe | C12: 2014 | D12: Petrol | E12: Automatic | G12: 176790 | H12: 178 | I12: 167 | J12: 2 | K12: 0 | M12: Red | N12: SUV | O12: RWD | P12: 33 | Q12: NY | R12: 4926
A13: Volkswagen | B13: Passat | C13: 2010 | D13: Petrol | E13: Automatic | F13: 2.3 | G13: 147198 | I13: 155 | J13: 3 | K13: 0 | L13: Partial Service | N13: Sedan | O13: FWD | Q13: NC | R13: 1022
A14: Toyota | B14: RAV4 | C14: 2019 | D14: Diesel | F14: 3.1 | G14: 66811 | H14: 233 | I14: 211 | J14: 1 | K14: 0 | L14: Partial Service | M14: Brown | N14: SUV | O14: AWD | P14: 25 | Q14: OH | R14: 14479
A15: BMW | B15: X3 | C15: 2024 | D15: Electric | F15: 0 | G15: 4423 | I15: 385 | J15: 1 | K15: 0 | M15: Red | N15: SUV | O15: AWD | P15: 130 | Q15: IL | R15: 49703
A16: Mercedes-Benz | B16: GLC | C16: 2009 | D16: Petrol | E16: Automatic | F16: 3.1 | G16: 163109 | H16: 227 | J16: 4 | K16: 0 | L16: Full Service | M16: Gray | N16: SUV | O16: AWD | P16: 26 | Q16: CA | R16: 5235
A17: Mercedes-Benz | B17: C-Class | C17: 2010 | D17: Petrol | E17: Manual | F17: 2 | G17: 17138 | H17: 169 | I17: 160 | J17: 3 | K17: 0 | L17: Partial Service | M17: Blue | N17: Sedan | O17: FWD | P17: 27 | Q17: NC | R17: 11728
A18: Hyundai | B18: Sonata | C18: 2020 | D18: Petrol | E18: Automatic | F18: 2.4 | G18: 61462 | H18: 179 | I18: 170 | J18: 2 | K18: 0 | L18: Partial Service | M18: Brown | N18: Sedan | O18: FWD | Q18: CA | R18: 13555
A19: Chevrolet | B19: Tahoe | C19: 2011 | D19: Petrol | E19: Automatic | F19: 3.3 | G19: 264441 | H19: 258 | I19: 252 | J19: 4 | K19: 0 | L19: Partial Service | M19: Gray | N19: SUV | O19: AWD | P19: 22 | Q19: TX | R19: 3395
A20: Honda | B20: CR-V | C20: 2024 | D20: Petrol | F20: 3.4 | G20: 100 | H20: 271 | I20: 260 | J20: 1 | K20: 0 | L20: No Service | M20: Red | N20: SUV | O20: AWD | P20: 22 | R20: 24018
A21: Mercedes-Benz | B21: E-Class | C21: 2016 | D21: Petrol | E21: Automatic | G21: 53789 | H21: 172 | I21: 158 | J21: 1 | K21: 0 | L21: No Service | N21: Sedan | O21: AWD | P21: 29 | Q21: CA | R21: 23787
A22: BMW | B22: 3 Series | C22: 2015 | D22: Diesel | E22: Automatic | G22: 173833 | H22: 116 | I22: 116 | J22: 2 | K22: 1 | M22: Black | N22: Sedan | O22: FWD | P22: 35 | Q22: NC | R22: 10558
A23: Audi | B23: Q7 | C23: 2016 | D23: Petrol | E23: Automatic | F23: 3.1 | G23: 111537 | H23: 243 | I23: 219 | J23: 2 | K23: 0 | L23: Partial Service | M23: Blue | N23: SUV | O23: AWD | P23: 21 | Q23: FL | R23: 23314
A24: Honda | B24: Civic | C24: 2008 | D24: Petrol | E24: Automatic | F24: 1.9 | G24: 99945 | H24: 148 | J24: 3 | K24: 1 | L24: No Service | M24: Black | N24: Sedan | O24: FWD | P24: 33 | Q24: PA | R24: 500
A25: BMW | B25: X5 | C25: 2021 | D25: Diesel | E25: Automatic | F25: 2.6 | G25: 49540 | H25: 213 | I25: 207 | J25: 1 | K25: 0 | L25: Partial Service | N25: SUV | O25: FWD | Q25: TX | R25: 44947
A26: Honda | B26: Accord | C26: 2021 | D26: Petrol | E26: Automatic | F26: 1.7 | G26: 60744 | H26: 137 | I26: 147 | J26: 1 | K26: 0 | L26: Full Service | M26: Blue | N26: Sedan | O26: FWD | Q26: FL | R26: 16814
A27: BMW | B27: 5 Series | C27: 2018 | D27: Petrol | E27: Automatic | F27: 2 | G27: 42807 | H27: 154 | I27: 148 | J27: 2 | L27: No Service | M27: Green | N27: Sedan | O27: FWD | P27: 41 | Q27: NC | R27: 31593
A28: BMW | B28: X5 | C28: 2013 | D28: Diesel | E28: Automatic | F28: 2.3 | G28: 261604 | H28: 181 | I28: 183 | J28: 2 | K28: 0 | L28: Full Service | M28: Silver | N28: SUV | O28: RWD | Q28: FL | R28: 11240
A29: Hyundai | B29: Sonata | C29: 2007 | D29: Petrol | E29: Manual | F29: 2.3 | G29: 188958 | H29: 170 | I29: 154 | J29: 2 | K29: 1 | L29: No Service | M29: Black | N29: Sedan | O29: FWD | P29: 32 | Q29: PA | R29: 500
A30: Ford | B30: Mustang | C30: 2010 | D30: Diesel | E30: Automatic | F30: 3.1 | G30: 34292 | H30: 245 | I30: 238 | J30: 3 | K30: 1 | L30: Partial Service | M30: Brown | N30: Coupe | O30: RWD | P30: 23 | Q30: FL | R30: 5739
A31: Ford | B31: F-150 | C31: 2018 | D31: Petrol | E31: Automatic | F31: 4.6 | G31: 86124 | H31: 334 | I31: 317 | J31: 1 | K31: 0 | L31: No Service | N31: Truck | O31: RWD | P31: 15 | Q31: IL | R31: 13537
A32: Volkswagen | B32: Tiguan | C32: 2005 | D32: Petrol | E32: Automatic | F32: 2.4 | G32: 292861 | H32: 178 | I32: 177 | J32: 3 | K32: 1 | L32: No Service | M32: Green | N32: SUV | O32: AWD | P32: 31 | R32: 500
A33: Toyota | B33: Camry | C33: 2021 | D33: Hybrid | E33: Automatic | F33: 2.5 | G33: 38991 | H33: 205 | I33: 207 | J33: 1 | K33: 0 | L33: Full Service | M33: Green | N33: Sedan | O33: AWD | P33: 43 | Q33: TX | R33: 18533
A34: Chevrolet | B34: Silverado | C34: 2006 | D34: Petrol | E34: Automatic | G34: 342829 | H34: 399 | I34: 369 | J34: 5 | K34: 0 | L34: Full Service | M34: Green | N34: Truck | O34: RWD | P34: 10 | Q34: NY | R34: 500
A35: Hyundai | B35: Santa Fe | C35: 2009 | D35: Petrol | E35: Automatic | F35: 3.2 | G35: 159873 | H35: 239 | I35: 219 | J35: 4 | K35: 1 | L35: No Service | M35: Brown | N35: SUV | O35: RWD | P35: 31 | Q35: NY | R35: 857
A36: Audi | B36: Q5 | C36: 2019 | D36: Petrol | E36: Automatic | F36: 2.7 | G36: 104624 | H36: 215 | I36: 187 | J36: 1 | L36: Full Service | M36: Green | N36: SUV | O36: AWD | P36: 26 | Q36: GA | R36: 23357
A37: Chevrolet | B37: Malibu | C37: 2018 | D37: Hybrid | E37: Automatic | F37: 1.8 | G37: 109872 | H37: 147 | I37: 143 | J37: 1 | K37: 0 | L37: No Service | M37: Gray | N37: Sedan | O37: FWD | P37: 35 | Q37: PA | R37: 7461
A38: BMW | B38: X3 | C38: 2022 | D38: Petrol | E38: Automatic | G38: 24031 | H38: 240 | I38: 220 | J38: 1 | K38: 0 | L38: No Service | N38: SUV | O38: AWD | P38: 27 | Q38: IL | R38: 33176
A39: Toyota | B39: Camry | C39: 2006 | D39: Petrol | E39: Manual | F39: 1.9 | G39: 26737 | H39: 164 | I39: 166 | J39: 4 | K39: 1 | L39: No Service | M39: Silver | N39: Sedan | O39: FWD | P39: 38 | Q39: OH | R39: 3239
A40: Toyota | B40: RAV4 | C40: 2010 | D40: Petrol | E40: Automatic | G40: 96089 | H40: 209 | I40: 194 | J40: 3 | K40: 1 | L40: Full Service | M40: Gray | N40: SUV | O40: AWD | P40: 34 | Q40: OH | R40: 3400
...

Sheet Data_Quality
A1: Column | B1: Missing Count | C1: Missing % | D1: Zero Count | E1: Median | F1: Treatment | G1: Outlier Check | H1: Analyst Note
A2: Transmission | B2: =COUNTBLANK(INDEX(automobile_dataset!$A$2:$R$5501,0,MATCH(A2,automobile_dataset!$A$1:$R$1,0))) -> 827 | C2: =B2/5500 -> 0.15036364 | D2: =COUNTIF(INDEX(automobile_dataset!$A$2:$R$5501,0,MATCH(A2,automobile_dataset!$A$1:$R$1,0)),0) -> 0 | E2: =IF(COUNT(INDEX(automobile_dataset!$A$2:$R$5501,0,MATCH(A2,automobile_dataset!$A$1:$R$1,0)))=0,"-",MEDIAN(INDEX(automobile_dataset!$A$2:$R$5501,0,MATCH(A2,automobile_dataset!$A$1:$R$1,0)))) -> - | F2: Use Unknown for missing categorical values | G2: Not checked | H2: Categorical field; missing values treated as Unknown
A3: Engine_Size | B3: =COUNTBLANK(INDEX(automobile_dataset!$A$2:$R$5501,0,MATCH(A3,automobile_dataset!$A$1:$R$1,0))) -> 844 | C3: =B3/5500 -> 0.15345455 | D3: =COUNTIF(INDEX(automobile_dataset!$A$2:$R$5501,0,MATCH(A3,automobile_dataset!$A$1:$R$1,0)),0) -> 127 | E3: =IF(COUNT(INDEX(automobile_dataset!$A$2:$R$5501,0,MATCH(A3,automobile_dataset!$A$1:$R$1,0)))=0,"-",MEDIAN(INDEX(automobile_dataset!$A$2:$R$5501,0,MATCH(A3,automobile_dataset!$A$1:$R$1,0)))) -> 2.4 | F3: Fill blanks with 2.4; keep 0 for EVs | G3: Checked | H3: 0 values correspond to EVs; retained as valid values
A4: Horsepower | B4: =COUNTBLANK(INDEX(automobile_dataset!$A$2:$R$5501,0,MATCH(A4,automobile_dataset!$A$1:$R$1,0))) -> 800 | C4: =B4/5500 -> 0.14545455 | D4: =COUNTIF(INDEX(automobile_dataset!$A$2:$R$5501,0,MATCH(A4,automobile_dataset!$A$1:$R$1,0)),0) -> 0 | E4: =IF(COUNT(INDEX(automobile_dataset!$A$2:$R$5501,0,MATCH(A4,automobile_dataset!$A$1:$R$1,0)))=0,"-",MEDIAN(INDEX(automobile_dataset!$A$2:$R$5501,0,MATCH(A4,automobile_dataset!$A$1:$R$1,0)))) -> 187 | F4: Fill blanks with 187 | G4: Checked | H4: 434 HP inspected; plausible high-performance value
A5: Torque | B5: =COUNTBLANK(INDEX(automobile_dataset!$A$2:$R$5501,0,MATCH(A5,automobile_dataset!$A$1:$R$1,0))) -> 799 | C5: =B5/5500 -> 0.14527273 | D5: =COUNTIF(INDEX(automobile_dataset!$A$2:$R$5501,0,MATCH(A5,automobile_dataset!$A$1:$R$1,0)),0) -> 0 | E5: =IF(COUNT(INDEX(automobile_dataset!$A$2:$R$5501,0,MATCH(A5,automobile_dataset!$A$1:$R$1,0)))=0,"-",MEDIAN(INDEX(automobile_dataset!$A$2:$R$5501,0,MATCH(A5,automobile_dataset!$A$1:$R$1,0)))) -> 178 | F5: Fill blanks with 178 | G5: Checked | H5: 443 torque inspected; retained as plausible high-performance value
A6: Accident_History | B6: =COUNTBLANK(INDEX(automobile_dataset!$A$2:$R$5501,0,MATCH(A6,automobile_dataset!$A$1:$R$1,0))) -> 812 | C6: =B6/5500 -> 0.14763636 | D6: =COUNTIF(INDEX(automobile_dataset!$A$2:$R$5501,0,MATCH(A6,automobile_dataset!$A$1:$R$1,0)),0) -> 2775 | E6: - | F6: Use Unknown for missing categorical values | G6: Not checked | H6: Categorical field; missing values treated as Unknown
A7: Service_History | B7: =COUNTBLANK(INDEX(automobile_dataset!$A$2:$R$5501,0,MATCH(A7,automobile_dataset!$A$1:$R$1,0))) -> 855 | C7: =B7/5500 -> 0.15545455 | D7: =COUNTIF(INDEX(automobile_dataset!$A$2:$R$5501,0,MATCH(A7,automobile_dataset!$A$1:$R$1,0)),0) -> 0 | E7: =IF(COUNT(INDEX(automobile_dataset!$A$2:$R$5501,0,MATCH(A7,automobile_dataset!$A$1:$R$1,0)))=0,"-",MEDIAN(INDEX(automobile_dataset!$A$2:$R$5501,0,MATCH(A7,automobile_dataset!$A$1:$R$1,0)))) -> - | F7: Use Unknown for missing categorical values | G7: Not checked | H7: Categorical field; missing values treated as Unknown
A8: Color | B8: =COUNTBLANK(INDEX(automobile_dataset!$A$2:$R$5501,0,MATCH(A8,automobile_dataset!$A$1:$R$1,0))) -> 803 | C8: =B8/5500 -> 0.146 | D8: =COUNTIF(INDEX(automobile_dataset!$A$2:$R$5501,0,MATCH(A8,automobile_dataset!$A$1:$R$1,0)),0) -> 0 | E8: =IF(COUNT(INDEX(automobile_dataset!$A$2:$R$5501,0,MATCH(A8,automobile_dataset!$A$1:$R$1,0)))=0,"-",MEDIAN(INDEX(automobile_dataset!$A$2:$R$5501,0,MATCH(A8,automobile_dataset!$A$1:$R$1,0)))) -> - | F8: Use Unknown for missing categorical values | G8: Not checked | H8: Categorical field; missing values treated as Unknown
A9: Fuel_Efficiency | B9: =COUNTBLANK(INDEX(automobile_dataset!$A$2:$R$5501,0,MATCH(A9,automobile_dataset!$A$1:$R$1,0))) -> 794 | C9: =B9/5500 -> 0.14436364 | D9: =COUNTIF(INDEX(automobile_dataset!$A$2:$R$5501,0,MATCH(A9,automobile_dataset!$A$1:$R$1,0)),0) -> 0 | E9: =IF(COUNT(INDEX(automobile_dataset!$A$2:$R$5501,0,MATCH(A9,automobile_dataset!$A$1:$R$1,0)))=0,"-",MEDIAN(INDEX(automobile_dataset!$A$2:$R$5501,0,MATCH(A9,automobile_dataset!$A$1:$R$1,0)))) -> 32 | F9: Fill blanks with median 32 | G9: Statistical outlier | H9: IQR range: 12–52. Values 10 and 141 are statistical outliers; retained after record-level review
A10: Location | B10: =COUNTBLANK(INDEX(automobile_dataset!$A$2:$R$5501,0,MATCH(A10,automobile_dataset!$A$1:$R$1,0))) -> 782 | C10: =B10/5500 -> 0.14218182 | D10: =COUNTIF(INDEX(automobile_dataset!$A$2:$R$5501,0,MATCH(A10,automobile_dataset!$A$1:$R$1,0)),0) -> 0 | E10: =IF(COUNT(INDEX(automobile_dataset!$A$2:$R$5501,0,MATCH(A10,automobile_dataset!$A$1:$R$1,0)))=0,"-",MEDIAN(INDEX(automobile_dataset!$A$2:$R$5501,0,MATCH(A10,automobile_dataset!$A$1:$R$1,0)))) -> - | F10: Use Unknown for missing categorical values | G10: Not checked | H10: Categorical field; missing values treated as Unknown
A11: Mileage | B11: =COUNTBLANK(INDEX(automobile_dataset!$A$2:$R$5501,0,MATCH(A11,automobile_dataset!$A$1:$R$1,0))) -> 0 | C11: =B11/5500 -> 0 | D11: =COUNTIF(INDEX(automobile_dataset!$A$2:$R$5501,0,MATCH(A11,automobile_dataset!$A$1:$R$1,0)),0) -> 0 | E11: =IF(COUNT(INDEX(automobile_dataset!$A$2:$R$5501,0,MATCH(A11,automobile_dataset!$A$1:$R$1,0)))=0,"-",MEDIAN(INDEX(automobile_dataset!$A$2:$R$5501,0,MATCH(A11,automobile_dataset!$A$1:$R$1,0)))) -> 96926.5 | F11: No missing treatment | G11: Potential extreme | H11: Max 536,731 km; retained pending analysis
A13: Fuel_Efficiency Outlier Check | D13: Mileage Outlier Check
A14: Metric | B14: Value | D14: Metric | E14: Value
A15: Q1 | B15: =_xlfn.QUARTILE.INC(automobile_dataset!$P$2:$P$5501,1) -> 27 | D15: Q1 | E15: 39112
A16: Q3 | B16: =_xlfn.QUARTILE.INC(automobile_dataset!$P$2:$P$5501,3) -> 37 | D16: Q3 | E16: 172757.5
A17: IQR | B17: =B16-B15 -> 10 | D17: IQR | E17: 133645.5
A18: Lower Limit | B18: =B15-(1.5*B17) -> 12 | D18: Lower Limit | E18: -161356.25
A19: Upper Limit | B19: =B16+(1.5*B17) -> 52 | D19: Upper Limit | E19: 373225.75
A20: Minimum Value | B20: =MIN(automobile_dataset!$P$2:$P$5501) -> 10 | D20: Minimum Value | E20: 100
A21: Maximum Value | B21: =MAX(automobile_dataset!$P$2:$P$5501) -> 141 | D21: Maximum Value | E21: 536731

Sheet Cleaned_Data
A1: Make | B1: Model | C1: Year | D1: Fuel_Type | E1: Transmission | F1: Engine_Size | G1: Mileage | H1: Horsepower | I1: Torque | J1: Owners | K1: Accident_History | L1: Service_History | M1: Color | N1: Body_Type | O1: Drivetrain | P1: Fuel_Efficiency | Q1: Location | R1: Selling_Price | S1: Mileage_Band
A2: Mercedes-Benz | B2: GLE | C2: 2024 | D2: Petrol | E2: Automatic | F2: 2.3 | G2: 100 | H2: 186 | I2: 196 | J2: 1 | K2: 0 | L2: Unknown | M2: Silver | N2: SUV | O2: AWD | P2: 30 | Q2: IL | R2: 64140 | S2: =IF(G2<=50000,"0-50K",IF(G2<=100000,"50K-100K",IF(G2<=150000,"100K-150K",IF(G2<=200000,"150K-200K","200K+")))) -> 0-50K
A3: Hyundai | B3: Tucson | C3: 2008 | D3: Petrol | E3: Automatic | F3: 2.3 | G3: 387035 | H3: 189 | I3: 190 | J3: 4 | K3: 0 | L3: Unknown | M3: Blue | N3: SUV | O3: FWD | P3: 35 | Q3: FL | R3: 500 | S3: =IF(G3<=50000,"0-50K",IF(G3<=100000,"50K-100K",IF(G3<=150000,"100K-150K",IF(G3<=200000,"150K-200K","200K+")))) -> 200K+
A4: Volkswagen | B4: Golf | C4: 2021 | D4: Hybrid | E4: Unknown | F4: 1.9 | G4: 46054 | H4: 158 | I4: 153 | J4: 1 | K4: 0 | L4: Partial Service | M4: Gray | N4: Hatchback | O4: AWD | P4: 43 | Q4: NY | R4: 16429 | S4: =IF(G4<=50000,"0-50K",IF(G4<=100000,"50K-100K",IF(G4<=150000,"100K-150K",IF(G4<=200000,"150K-200K","200K+")))) -> 0-50K
A5: Chevrolet | B5: Tahoe | C5: 2005 | D5: Petrol | E5: Unknown | F5: 2.2 | G5: 141302 | H5: 169 | I5: 165 | J5: 5 | K5: 1 | L5: No Service | M5: Blue | N5: SUV | O5: AWD | P5: 32 | Q5: FL | R5: 2199 | S5: =IF(G5<=50000,"0-50K",IF(G5<=100000,"50K-100K",IF(G5<=150000,"100K-150K",IF(G5<=200000,"150K-200K","200K+")))) -> 100K-150K
A6: Toyota | B6: Camry | C6: 2022 | D6: Petrol | E6: Automatic | F6: 1.9 | G6: 32813 | H6: 149 | I6: 141 | J6: 1 | K6: 0 | L6: Full Service | M6: Brown | N6: Sedan | O6: FWD | P6: 38 | Q6: CA | R6: 21792 | S6: =IF(G6<=50000,"0-50K",IF(G6<=100000,"50K-100K",IF(G6<=150000,"100K-150K",IF(G6<=200000,"150K-200K","200K+")))) -> 0-50K
A7: Chevrolet | B7: Equinox | C7: 2008 | D7: Petrol | E7: Unknown | F7: 2.7 | G7: 60654 | H7: 212 | I7: 207 | J7: 3 | K7: 0 | L7: Unknown | M7: Blue | N7: SUV | O7: AWD | P7: 25 | Q7: TX | R7: 3421 | S7: =IF(G7<=50000,"0-50K",IF(G7<=100000,"50K-100K",IF(G7<=150000,"100K-150K",IF(G7<=200000,"150K-200K","200K+")))) -> 50K-100K
A8: Nissan | B8: Sentra | C8: 2022 | D8: Petrol | E8: Automatic | F8: 2.2 | G8: 7444 | H8: 187 | I8: 180 | J8: 1 | K8: 0 | L8: Full Service | M8: Gray | N8: Sedan | O8: AWD | P8: 34 | Q8: IL | R8: 17145 | S8: =IF(G8<=50000,"0-50K",IF(G8<=100000,"50K-100K",IF(G8<=150000,"100K-150K",IF(G8<=200000,"150K-200K","200K+")))) -> 0-50K
A9: Mercedes-Benz | B9: C-Class | C9: 2022 | D9: Petrol | E9: Automatic | F9: 2.3 | G9: 32133 | H9: 180 | I9: 162 | J9: 1 | K9: 0 | L9: Partial Service | M9: Green | N9: Sedan | O9: FWD | P9: 35 | Q9: NY | R9: 31416 | S9: =IF(G9<=50000,"0-50K",IF(G9<=100000,"50K-100K",IF(G9<=150000,"100K-150K",IF(G9<=200000,"150K-200K","200K+")))) -> 0-50K
A10: BMW | B10: X3 | C10: 2023 | D10: Petrol | E10: Automatic | F10: 2.5 | G10: 1553 | H10: 203 | I10: 179 | J10: 1 | K10: 0 | L10: Full Service | M10: Unknown | N10: SUV | O10: AWD | P10: 25 | Q10: FL | R10: 43914 | S10: =IF(G10<=50000,"0-50K",IF(G10<=100000,"50K-100K",IF(G10<=150000,"100K-150K",IF(G10<=200000,"150K-200K","200K+")))) -> 0-50K
A11: Honda | B11: Pilot | C11: 2020 | D11: Hybrid | E11: Automatic | F11: 2.1 | G11: 12494 | H11: 178 | I11: 168 | J11: 1 | K11: Unknown | L11: No Service | M11: Blue | N11: SUV | O11: FWD | P11: 44 | Q11: NC | R11: 22311 | S11: =IF(G11<=50000,"0-50K",IF(G11<=100000,"50K-100K",IF(G11<=150000,"100K-150K",IF(G11<=200000,"150K-200K","200K+")))) -> 0-50K
A12: Hyundai | B12: Santa Fe | C12: 2014 | D12: Petrol | E12: Automatic | F12: 2.5 | G12: 176790 | H12: 178 | I12: 167 | J12: 2 | K12: 0 | L12: Unknown | M12: Red | N12: SUV | O12: RWD | P12: 33 | Q12: NY | R12: 4926 | S12: =IF(G12<=50000,"0-50K",IF(G12<=100000,"50K-100K",IF(G12<=150000,"100K-150K",IF(G12<=200000,"150K-200K","200K+")))) -> 150K-200K
A13: Volkswagen | B13: Passat | C13: 2010 | D13: Petrol | E13: Automatic | F13: 2.3 | G13: 147198 | H13: 187 | I13: 155 | J13: 3 | K13: 0 | L13: Partial Service | M13: Unknown | N13: Sedan | O13: FWD | P13: 32 | Q13: NC | R13: 1022 | S13: =IF(G13<=50000,"0-50K",IF(G13<=100000,"50K-100K",IF(G13<=150000,"100K-150K",IF(G13<=200000,"150K-200K","200K+")))) -> 100K-150K
A14: Toyota | B14: RAV4 | C14: 2019 | D14: Diesel | E14: Unknown | F14: 3.1 | G14: 66811 | H14: 233 | I14: 211 | J14: 1 | K14: 0 | L14: Partial Service | M14: Brown | N14: SUV | O14: AWD | P14: 25 | Q14: OH | R14: 14479 | S14: =IF(G14<=50000,"0-50K",IF(G14<=100000,"50K-100K",IF(G14<=150000,"100K-150K",IF(G14<=200000,"150K-200K","200K+")))) -> 50K-100K
A15: BMW | B15: X3 | C15: 2024 | D15: Electric | E15: Unknown | F15: 0 | G15: 4423 | H15: 187 | I15: 385 | J15: 1 | K15: 0 | L15: Unknown | M15: Red | N15: SUV | O15: AWD | P15: 130 | Q15: IL | R15: 49703 | S15: =IF(G15<=50000,"0-50K",IF(G15<=100000,"50K-100K",IF(G15<=150000,"100K-150K",IF(G15<=200000,"150K-200K","200K+")))) -> 0-50K
A16: Mercedes-Benz | B16: GLC | C16: 2009 | D16: Petrol | E16: Automatic | F16: 3.1 | G16: 163109 | H16: 227 | I16: 187 | J16: 4 | K16: 0 | L16: Full Service | M16: Gray | N16: SUV | O16: AWD | P16: 26 | Q16: CA | R16: 5235 | S16: =IF(G16<=50000,"0-50K",IF(G16<=100000,"50K-100K",IF(G16<=150000,"100K-150K",IF(G16<=200000,"150K-200K","200K+")))) -> 150K-200K
A17: Mercedes-Benz | B17: C-Class | C17: 2010 | D17: Petrol | E17: Manual | F17: 2 | G17: 17138 | H17: 169 | I17: 160 | J17: 3 | K17: 0 | L17: Partial Service | M17: Blue | N17: Sedan | O17: FWD | P17: 27 | Q17: NC | R17: 11728 | S17: =IF(G17<=50000,"0-50K",IF(G17<=100000,"50K-100K",IF(G17<=150000,"100K-150K",IF(G17<=200000,"150K-200K","200K+")))) -> 0-50K
A18: Hyundai | B18: Sonata | C18: 2020 | D18: Petrol | E18: Automatic | F18: 2.4 | G18: 61462 | H18: 179 | I18: 170 | J18: 2 | K18: 0 | L18: Partial Service | M18: Brown | N18: Sedan | O18: FWD | P18: 32 | Q18: CA | R18: 13555 | S18: =IF(G18<=50000,"0-50K",IF(G18<=100000,"50K-100K",IF(G18<=150000,"100K-150K",IF(G18<=200000,"150K-200K","200K+")))) -> 50K-100K
A19: Chevrolet | B19: Tahoe | C19: 2011 | D19: Petrol | E19: Automatic | F19: 3.3 | G19: 264441 | H19: 258 | I19: 252 | J19: 4 | K19: 0 | L19: Partial Service | M19: Gray | N19: SUV | O19: AWD | P19: 22 | Q19: TX | R19: 3395 | S19: =IF(G19<=50000,"0-50K",IF(G19<=100000,"50K-100K",IF(G19<=150000,"100K-150K",IF(G19<=200000,"150K-200K","200K+")))) -> 200K+
A20: Honda | B20: CR-V | C20: 2024 | D20: Petrol | E20: Unknown | F20: 3.4 | G20: 100 | H20: 271 | I20: 252 | J20: 1 | K20: 0 | L20: No Service | M20: Red | N20: SUV | O20: AWD | P20: 22 | Q20: Unknown | R20: 24018 | S20: =IF(G20<=50000,"0-50K",IF(G20<=100000,"50K-100K",IF(G20<=150000,"100K-150K",IF(G20<=200000,"150K-200K","200K+")))) -> 0-50K
A21: Mercedes-Benz | B21: E-Class | C21: 2016 | D21: Petrol | E21: Automatic | F21: 2.5 | G21: 53789 | H21: 172 | I21: 158 | J21: 1 | K21: 0 | L21: No Service | M21: Unknown | N21: Sedan | O21: AWD | P21: 29 | Q21: CA | R21: 23787 | S21: =IF(G21<=50000,"0-50K",IF(G21<=100000,"50K-100K",IF(G21<=150000,"100K-150K",IF(G21<=200000,"150K-200K","200K+")))) -> 50K-100K
A22: BMW | B22: 3 Series | C22: 2015 | D22: Diesel | E22: Automatic | F22: 2.5 | G22: 173833 | H22: 116 | I22: 116 | J22: 2 | K22: 1 | L22: Unknown | M22: Black | N22: Sedan | O22: FWD | P22: 35 | Q22: NC | R22: 10558 | S22: =IF(G22<=50000,"0-50K",IF(G22<=100000,"50K-100K",IF(G22<=150000,"100K-150K",IF(G22<=200000,"150K-200K","200K+")))) -> 150K-200K
A23: Audi | B23: Q7 | C23: 2016 | D23: Petrol | E23: Automatic | F23: 3.1 | G23: 111537 | H23: 243 | I23: 219 | J23: 2 | K23: 0 | L23: Partial Service | M23: Blue | N23: SUV | O23: AWD | P23: 21 | Q23: FL | R23: 23314 | S23: =IF(G23<=50000,"0-50K",IF(G23<=100000,"50K-100K",IF(G23<=150000,"100K-150K",IF(G23<=200000,"150K-200K","200K+")))) -> 100K-150K
... A26: Honda | B26: Accord | C26: 2021 | D26: Petrol | E26: Automatic | F26: 1.7 | G26: 60744 | H26: 137 | I26: 147 | J26: 1 | K26: 0 | L26: Full Service | M26: Blue | N26: Sedan | O26: FWD | P26: 32 | Q26: FL | R26: 16814 | S26: =IF(G26<=50000,"0-50K",IF(G26<=100000,"50K-100K",IF(G26<=150000,"100K-150K",IF(G26<=200000,"150K-200K","200K+")))) -> 50K-100K
A27: BMW | B27: 5 Series | C27: 2018 | D27: Petrol | E27: Automatic | F27: 2 | G27: 42807 | H27: 154 | I27: 148 | J27: 2 | K27: Unknown | L27: No Service | M27: Green | N27: Sedan | O27: FWD | P27: 41 | Q27: NC | R27: 31593 | S27: =IF(G27<=50000,"0-50K",IF(G27<=100000,"50K-100K",IF(G27<=150000,"100K-150K",IF(G27<=200000,"150K-200K","200K+")))) -> 0-50K
A28: BMW | B28: X5 | C28: 2013 | D28: Diesel | E28: Automatic | F28: 2.3 | G28: 261604 | H28: 181 | I28: 183 | J28: 2 | K28: 0 | L28: Full Service | M28: Silver | N28: SUV | O28: RWD | P28: 32 | Q28: FL | R28: 11240 | S28: =IF(G28<=50000,"0-50K",IF(G28<=100000,"50K-100K",IF(G28<=150000,"100K-150K",IF(G28<=200000,"150K-200K","200K+")))) -> 200K+
A29: Hyundai | B29: Sonata | C29: 2007 | D29: Petrol | E29: Manual | F29: 2.3 | G29: 188958 | H29: 170 | I29: 154 | J29: 2 | K29: 1 | L29: No Service | M29: Black | N29: Sedan | O29: FWD | P29: 32 | Q29: PA | R29: 500 | S29: =IF(G29<=50000,"0-50K",IF(G29<=100000,"50K-100K",IF(G29<=150000,"100K-150K",IF(G29<=200000,"150K-200K","200K+")))) -> 150K-200K
A30: Ford | B30: Mustang | C30: 2010 | D30: Diesel | E30: Automatic | F30: 3.1 | G30: 34292 | H30: 245 | I30: 238 | J30: 3 | K30: 1 | L30: Partial Service | M30: Brown | N30: Coupe | O30: RWD | P30: 23 | Q30: FL | R30: 5739 | S30: =IF(G30<=50000,"0-50K",IF(G30<=100000,"50K-100K",IF(G30<=150000,"100K-150K",IF(G30<=200000,"150K-200K","200K+")))) -> 0-50K
A31: Ford | B31: F-150 | C31: 2018 | D31: Petrol | E31: Automatic | F31: 4.6 | G31: 86124 | H31: 334 | I31: 317 | J31: 1 | K31: 0 | L31: No Service | M31: Unknown | N31: Truck | O31: RWD | P31: 15 | Q31: IL | R31: 13537 | S31: =IF(G31<=50000,"0-50K",IF(G31<=100000,"50K-100K",IF(G31<=150000,"100K-150K",IF(G31<=200000,"150K-200K","200K+")))) -> 50K-100K
A32: Volkswagen | B32: Tiguan | C32: 2005 | D32: Petrol | E32: Automatic | F32: 2.4 | G32: 292861 | H32: 178 | I32: 177 | J32: 3 | K32: 1 | L32: No Service | M32: Green | N32: SUV | O32: AWD | P32: 31 | Q32: Unknown | R32: 500 | S32: =IF(G32<=50000,"0-50K",IF(G32<=100000,"50K-100K",IF(G32<=150000,"100K-150K",IF(G32<=200000,"150K-200K","200K+")))) -> 200K+
A33: Toyota | B33: Camry | C33: 2021 | D33: Hybrid | E33: Automatic | F33: 2.5 | G33: 38991 | H33: 205 | I33: 207 | J33: 1 | K33: 0 | L33: Full Service | M33: Green | N33: Sedan | O33: AWD | P33: 43 | Q33: TX | R33: 18533 | S33: =IF(G33<=50000,"0-50K",IF(G33<=100000,"50K-100K",IF(G33<=150000,"100K-150K",IF(G33<=200000,"150K-200K","200K+")))) -> 0-50K
A34: Chevrolet | B34: Silverado | C34: 2006 | D34: Petrol | E34: Automatic | F34: 2.5 | G34: 342829 | H34: 399 | I34: 369 | J34: 5 | K34: 0 | L34: Full Service | M34: Green | N34: Truck | O34: RWD | P34: 10 | Q34: NY | R34: 500 | S34: =IF(G34<=50000,"0-50K",IF(G34<=100000,"50K-100K",IF(G34<=150000,"100K-150K",IF(G34<=200000,"150K-200K","200K+")))) -> 200K+
A35: Hyundai | B35: Santa Fe | C35: 2009 | D35: Petrol | E35: Automatic | F35: 3.2 | G35: 159873 | H35: 239 | I35: 219 | J35: 4 | K35: 1 | L35: No Service | M35: Brown | N35: SUV | O35: RWD | P35: 31 | Q35: NY | R35: 857 | S35: =IF(G35<=50000,"0-50K",IF(G35<=100000,"50K-100K",IF(G35<=150000,"100K-150K",IF(G35<=200000,"150K-200K","200K+")))) -> 150K-200K
A36: Audi | B36: Q5 | C36: 2019 | D36: Petrol | E36: Automatic | F36: 2.7 | G36: 104624 | H36: 215 | I36: 187 | J36: 1 | K36: Unknown | L36: Full Service | M36: Green | N36: SUV | O36: AWD | P36: 26 | Q36: GA | R36: 23357 | S36: =IF(G36<=50000,"0-50K",IF(G36<=100000,"50K-100K",IF(G36<=150000,"100K-150K",IF(G36<=200000,"150K-200K","200K+")))) -> 100K-150K
A37: Chevrolet | B37: Malibu | C37: 2018 | D37: Hybrid | E37: Automatic | F37: 1.8 | G37: 109872 | H37: 147 | I37: 143 | J37: 1 | K37: 0 | L37: No Service | M37: Gray | N37: Sedan | O37: FWD | P37: 35 | Q37: PA | R37: 7461 | S37: =IF(G37<=50000,"0-50K",IF(G37<=100000,"50K-100K",IF(G37<=150000,"100K-150K",IF(G37<=200000,"150K-200K","200K+")))) -> 100K-150K
A38: BMW | B38: X3 | C38: 2022 | D38: Petrol | E38: Automatic | F38: 2.5 | G38: 24031 | H38: 240 | I38: 220 | J38: 1 | K38: 0 | L38: No Service | M38: Unknown | N38: SUV | O38: AWD | P38: 27 | Q38: IL | R38: 33176 | S38: =IF(G38<=50000,"0-50K",IF(G38<=100000,"50K-100K",IF(G38<=150000,"100K-150K",IF(G38<=200000,"150K-200K","200K+")))) -> 0-50K
A39: Toyota | B39: Camry | C39: 2006 | D39: Petrol | E39: Manual | F39: 1.9 | G39: 26737 | H39: 164 | I39: 166 | J39: 4 | K39: 1 | L39: No Service | M39: Silver | N39: Sedan | O39: FWD | P39: 38 | Q39: OH | R39: 3239 | S39: =IF(G39<=50000,"0-50K",IF(G39<=100000,"50K-100K",IF(G39<=150000,"100K-150K",IF(G39<=200000,"150K-200K","200K+")))) -> 0-50K
A40: Toyota | B40: RAV4 | C40: 2010 | D40: Petrol | E40: Automatic | F40: 2.5 | G40: 96089 | H40: 209 | I40: 194 | J40: 3 | K40: 1 | L40: Full Service | M40: Gray | N40: SUV | O40: AWD | P40: 34 | Q40: OH | R40: 3400 | S40: =IF(G40<=50000,"0-50K",IF(G40<=100000,"50K-100K",IF(G40<=150000,"100K-150K",IF(G40<=200000,"150K-200K","200K+")))) -> 50K-100K
A41: Audi | B41: A4 | C41: 2021 | D41: Petrol | E41: Automatic | F41: 2.5 | G41: 34375 | H41: 201 | I41: 181 | J41: 1 | K41: 0 | L41: Unknown | M41: Gray | N41: Sedan | O41: FWD | P41: 30 | Q41: IL | R41: 31213 | S41: =IF(G41<=50000,"0-50K",IF(G41<=100000,"50K-100K",IF(G41<=150000,"100K-150K",IF(G41<=200000,"150K-200K","200K+")))) -> 0-50K
A42: Chevrolet | B42: Malibu | C42: 2013 | D42: Petrol | E42: Automatic | F42: 1.6 | G42: 144687 | H42: 149 | I42: 133 | J42: 3 | K42: 0 | L42: Partial Service | M42: Unknown | N42: Sedan | O42: FWD | P42: 34 | Q42: MI | R42: 1931 | S42: =IF(G42<=50000,"0-50K",IF(G42<=100000,"50K-100K",IF(G42<=150000,"100K-150K",IF(G42<=200000,"150K-200K","200K+")))) -> 100K-150K
...

Sheet EDA
A1: Selling Price Overview | E1: Fuel Type Analysis | H1: Year Analysis | K1: Body Type Analysis
A2: Metric | B2: Value | C2: Interpretation | E2: Fuel_Type | F2: Average Selling_Price | H2: Year | I2: Average Selling_Price | K2: Body_Type | L2: Average Selling_Price
A3: Mean Selling Price | B3: =AVERAGE(Cleaned_Data!R2:R5501) -> 12319.874 | C3: Average selling price | E3: Petrol | F3: 11394.321 | H3: 2005 | I3: 883.25979 | K3: Hatchback | L3: 6569.4419
A4: Median Selling Price | B4: =MEDIAN(Cleaned_Data!R2:R5501) -> 8586 | C4: Typical middle value | E4: Diesel | F4: 13202.16 | H4: 2006 | I4: 1241.4081 | K4: Coupe | L4: 8696.9329
A5: Minimum Selling Price | B5: =MIN(Cleaned_Data!R2:R5501) -> 500 | C5: Lowest price | E5: Hybrid | F5: 16284.367 | H5: 2007 | I5: 1414.69 | K5: Sedan | L5: 11297.241
A6: Maximum Selling Price | B6: =MAX(Cleaned_Data!R2:R5501) -> 86692 | C6: Highest price | E6: Electric | F6: 21521.662 | H6: 2008 | I6: 2059.5254 | K6: Truck | L6: 12572.312
E7: Grand Total | F7: 12319.874 | H7: 2009 | I7: 2482.242 | K7: SUV | L7: 13615.431
A8: Brand Analysis | H8: 2010 | I8: 3470.721 | K8: Grand Total | L8: 12319.874
A9: Make | B9: Average Selling_Price | E9: Transmission Analysis | H9: 2011 | I9: 3990
A10: Mercedes-Benz | B10: 20482.828 | E10: Transmission | F10: Average Selling_Price | H10: 2012 | I10: 5492.6376 | K10: Accident History Analysis
A11: BMW | B11: 19459.025 | E11: Automatic | F11: 13555.223 | H11: 2013 | I11: 6586.1095 | K11: Accident_History | L11: Average Selling_Price
A12: Audi | B12: 19326.273 | E12: Manual | F12: 2895.0829 | H12: 2014 | I12: 8432.9853 | K12: 0 | L12: 16337.674
A13: Chevrolet | B13: 11579.743 | E13: Unknown | F13: 12184.137 | H13: 2015 | I13: 10195.007 | K13: Unknown | L13: 12770.081
A14: Ford | B14: 10084.565 | E14: Grand Total | F14: 12319.874 | H14: 2016 | I14: 11819.037 | K14: 1 | L14: 6300.551
A15: Honda | B15: 9460.481 | H15: 2017 | I15: 13669.498 | K15: Grand Total | L15: 12319.874
A16: Volkswagen | B16: 9327.1125 | E16: Mileage Analysis | H16: 2018 | I16: 15322.559
A17: Toyota | B17: 8589.2655 | E17: Mileage_Band | F17: Average Selling_Price | H17: 2019 | I17: 18645.444 | K17: Owners Analysis
A18: Nissan | B18: 8240.3801 | E18: 0-50K | F18: 25057.329 | H18: 2020 | I18: 21370.216 | K18: Owners | L18: Average Selling_Price
A19: Hyundai | B19: 7725.3074 | E19: 50K-100K | F19: 13271.587 | H19: 2021 | I19: 24434.942 | K19: 1 | L19: 25009.003
A20: Grand Total | B20: 12319.874 | E20: 100K-150K | F20: 7477.61 | H20: 2022 | I20: 28529.004 | K20: 2 | L20: 11096.643
E21: 150K-200K | F21: 3389.5277 | H21: 2023 | I21: 30551.872 | K21: 3 | L21: 6162.2446
E22: 200K+ | F22: 1176.1944 | H22: 2024 | I22: 35423.806 | K22: 4 | L22: 2988.1611
E23: Grand Total | F23: 12319.874 | H23: Grand Total | I23: 12319.874 | K23: 5 | L23: 1647.813
K24: Grand Total | L24: 12319.874

Sheet Charts
A16: Mercedes-Benz has the highest average selling price, while Hyundai has the lowest. | I16: Automatic vehicles have a much higher average selling price than Manual vehicles. | Q16: Average selling price decreases sharply as mileage increases.
A32: Electric vehicles have the highest average selling price, followed by Hybrid vehicles.
I33: Average selling price shows a strong upward trend for newer model years. | Q33: SUVs have the highest average selling price, while Hatchbacks have the lowest.
A50: Vehicles with no recorded accidents have a higher average selling price than accident-recorded vehicles. | N50: Average selling price declines substantially as the number of previous owners increases.
